[32m2025-09-15 17:04:52 -0600[0m - dagster - [34mDEBUG[0m - __ASSET_JOB - facf8bd9-1637-40c6-9abb-63671218d42d - 90729 - LOGS_CAPTURED - Started capturing logs in process (pid: 90729).
[32m2025-09-15 17:04:52 -0600[0m - dagster - [34mDEBUG[0m - __ASSET_JOB - facf8bd9-1637-40c6-9abb-63671218d42d - 90729 - nfl_games - STEP_START - Started execution of step "nfl_games".
[32m2025-09-15 17:04:52 -0600[0m - dagster - [34mINFO[0m - __ASSET_JOB - facf8bd9-1637-40c6-9abb-63671218d42d - nfl_games - Loading NFL games data for seasons: [2020, 2021, 2022, 2023, 2024]
[32m2025-09-15 17:04:53 -0600[0m - dagster - [34mINFO[0m - __ASSET_JOB - facf8bd9-1637-40c6-9abb-63671218d42d - nfl_games - Loaded 1408 games
[32m2025-09-15 17:05:02 -0600[0m - dagster - [34mERROR[0m - [31m__ASSET_JOB - facf8bd9-1637-40c6-9abb-63671218d42d - 90729 - nfl_games - STEP_FAILURE - Execution of step "nfl_games" failed.

dagster._core.errors.DagsterExecutionStepExecutionError: Error occurred while executing op "nfl_games"::

google.auth.exceptions.DefaultCredentialsError: Your default credentials were not found. To set up Application Default Credentials, see https://cloud.google.com/docs/authentication/external/set-up-adc for more information.

Stack Trace:
  File "/Users/matthewdwyer/Documents/nfl_v2/.venv/lib/python3.13/site-packages/dagster/_core/execution/plan/utils.py", line 57, in op_execution_error_boundary
    yield
  File "/Users/matthewdwyer/Documents/nfl_v2/.venv/lib/python3.13/site-packages/dagster/_utils/__init__.py", line 392, in iterate_with_context
    next_output = next(iterator)
  File "/Users/matthewdwyer/Documents/nfl_v2/.venv/lib/python3.13/site-packages/dagster/_core/execution/plan/compute_generator.py", line 137, in _coerce_op_compute_fn_to_iterator
    result = invoke_compute_fn(
        fn, context, kwargs, context_arg_provided, config_arg_class, resource_arg_mapping
    )
  File "/Users/matthewdwyer/Documents/nfl_v2/.venv/lib/python3.13/site-packages/dagster/_core/execution/plan/compute_generator.py", line 117, in invoke_compute_fn
    return fn(context, **args_to_pass) if context_arg_provided else fn(**args_to_pass)
           ~~^^^^^^^^^^^^^^^^^^^^^^^^^
  File "/Users/matthewdwyer/Documents/nfl_v2/pipeline/assets/nfl_games.py", line 15, in nfl_games
    store_dataframe_in_bigquery(context, games, "games")
    ~~~~~~~~~~~~~~~~~~~~~~~~~~~^^^^^^^^^^^^^^^^^^^^^^^^^
  File "/Users/matthewdwyer/Documents/nfl_v2/pipeline/utils/bigquery_client.py", line 15, in store_dataframe_in_bigquery
    client = get_bigquery_client()
  File "/Users/matthewdwyer/Documents/nfl_v2/pipeline/utils/bigquery_client.py", line 6, in get_bigquery_client
    return bigquery.Client()
           ~~~~~~~~~~~~~~~^^
  File "/Users/matthewdwyer/Documents/nfl_v2/.venv/lib/python3.13/site-packages/google/cloud/bigquery/client.py", line 261, in __init__
    super(Client, self).__init__(
    ~~~~~~~~~~~~~~~~~~~~~~~~~~~~^
        project=project,
        ^^^^^^^^^^^^^^^^
    ...<2 lines>...
        _http=_http,
        ^^^^^^^^^^^^
    )
    ^
  File "/Users/matthewdwyer/Documents/nfl_v2/.venv/lib/python3.13/site-packages/google/cloud/client/__init__.py", line 338, in __init__
    _ClientProjectMixin.__init__(self, project=project, credentials=credentials)
    ~~~~~~~~~~~~~~~~~~~~~~~~~~~~^^^^^^^^^^^^^^^^^^^^^^^^^^^^^^^^^^^^^^^^^^^^^^^^
  File "/Users/matthewdwyer/Documents/nfl_v2/.venv/lib/python3.13/site-packages/google/cloud/client/__init__.py", line 286, in __init__
    project = self._determine_default(project)
  File "/Users/matthewdwyer/Documents/nfl_v2/.venv/lib/python3.13/site-packages/google/cloud/client/__init__.py", line 305, in _determine_default
    return _determine_default_project(project)
  File "/Users/matthewdwyer/Documents/nfl_v2/.venv/lib/python3.13/site-packages/google/cloud/_helpers/__init__.py", line 152, in _determine_default_project
    _, project = google.auth.default()
                 ~~~~~~~~~~~~~~~~~~~^^
  File "/Users/matthewdwyer/Documents/nfl_v2/.venv/lib/python3.13/site-packages/google/auth/_default.py", line 685, in default
    raise exceptions.DefaultCredentialsError(_CLOUD_SDK_MISSING_CREDENTIALS)
[0m
